<?xml version="1.0" ?>
<robot name="roswell" xmlns:xacro="http://www.ros.org/wiki/xacro">
<!-- =================================================================================== -->
<!-- |    This document was autogenerated by xacro from roswell.urdf.xacro             | -->
<!-- |    EDITING THIS FILE BY HAND IS NOT RECOMMENDED                                 | -->
<!-- =================================================================================== -->
  <!-- deck to arm_link at max height-->
  <!-- deck to top of 80/20 -->
  <!-- The following included files set up definitions of parts of the robot body -->
  <material name="Black">
    <color rgba="0.2 0.2 0.2 1.0"/>
  </material>
  <material name="Orange">
    <color rgba="1.0  0.55 0.0 1.0"/>
  </material>
  <material name="Grey">
    <color rgba="0.7 0.7 0.7 1.0"/>
  </material>
  <material name="Red">
    <color rgba="0.8 0.0 0.0 1.0"/>
  </material>
  <material name="White">
    <color rgba="1.0 1.0 1.0 1.0"/>
  </material>
  <material name="Blue">
    <color rgba="0.0 0.0 0.8 1.0"/>
  </material>
  <!-- Now we can start using the macros included above to define the actual Maxwell -->
<!-- ARD: in pr2lite, but not required for roswell
  <link name="base_footprint">
    <visual>
      <origin rpy="0 0 0" xyz="0.0 0.0 0.00889"/>
      <geometry>
        <box size="0.001 0.001 0.001"/>
      </geometry>
      <material name="Green"/>
    </visual>
    <collision>
      <origin rpy="0 0 0" xyz="0.0 0.0 0.00889"/>
      <geometry>
        <box size="0.001 0.001 0.001"/>
      </geometry>
    </collision>
  </link>
  <joint name="base_footprint_joint" type="fixed">
    <origin rpy="0 0 0" xyz="0.0 0.0 0.0"/>
    <parent link="base_footprint"/>
    <child link="base_link"/>
  </joint>
-->
  <link name="base_link">
    <!-- links with zero principal moment of inertia (ixx, iyy, izz)
    could lead to infinite acceleration under any finite torque application.-->
    <inertial>
      <!-- turtlebot: 2.4/2.6 kg for small/big battery pack -->
      <!-- our 12v 7ah slc batter is appro 2.0 kg / 4.5 lb  -->
      <!-- plus weight of the laptop, extra battery etc.    -->
      <!-- castor as additional weight on the back          -->
<!--
      Note: mass and inertial effects xyz
      does gazebo combine fixed inertias?
      <origin rpy="0 0 0" xyz="-0.24 0 -0.62" />
      <box size="0.4064 0.4064 0.06"/>
-->
      <origin rpy="0 0 0" xyz="-0.24 0 -0.06" />
      <mass value="4" /> 
      <inertia ixx=".059" ixy="0.00" ixz="0.00" iyy=".10667" iyz="-0.00" izz=".059" />
<!-- tb3
      <inertia ixx="0.01" ixy="0.0" ixz="0.0"
               iyy="0.01" iyz="0.0"
               izz="0.01" />


-->


<!-- fetch (?) too far forward?
      <inertia ixx="1.225" ixy="0.0099" ixz="0.0062" iyx="0.0099" iyy="1.2853" iyz="-0.0034" izx="0.0062" izy="-0.0034" izz="0.987" />
     turtlebot inertia
      <inertia ixx="0.0001" ixy="0.0" ixz="0.0" iyy="0.0001" iyz="0.0" izz="0.0001"/>
      freight inertia:
      <inertia ixx="1.225" ixy="0.0099" ixz="0.0062" iyy="1.2853" iyz="-0.0034" izz="0.987" />

      for solid box with center of mass:
      xx = m(h2+d2)/ 12  yy= m(w2+d2)/12, zzz = m(w2+d2)/12
      zz == xx =  4 *(.017+.16)/12 = .059
      yy =  4 *(.16+.16)/12 = .10667

      For a 4 kg mass:
      <inertia ixx=".059" ixy="0.00" ixz="0.00" iyy=".10667" iyz="-0.00" izz=".059" />
-->
    </inertial>

    <visual>
      <origin rpy="0 0 0" xyz="0 0 0.0238"/>
      <geometry>
        <mesh filename="package://roswell_defs/meshes/base.stl"/>
      </geometry>
      <material name="Black"/>
    </visual>
    <collision>
<!--
      <origin rpy="0 0 0" xyz="-0.12065 0 0.0655"/>
      <origin rpy="0 0 0" xyz="0 0 0.0238"/>
-->
      <origin rpy="0 0 0" xyz="-0.12065 0 0.0655"/>
      <geometry>
        <!-- maxwell had false contacts, and no castor -->
<!--
        <box size="0.4064 0.4064 0.06"/>
        <box size="0.2064 0.2064 0.02"/>
-->
        <box size="0.4064 0.4064 0.06"/>
      </geometry>
    </collision>
  </link>
  <joint name="base_laser_joint" type="fixed">
<!--
    <axis xyz="0 1 -1"/>
    <origin rpy="3.1415 0 3.1415" xyz="0.0318 0 0.2"/>
    maxwell: <origin rpy="0 0 0" xyz="0.0318 0 0.1885"/>
-->
    <axis xyz="0 1 0"/>
    <origin rpy="3.1415 0 0" xyz="0.08 0 0.15"/>
    <parent link="base_link"/>
    <child link="base_laser_link"/>
  </joint>
<!-- ARD remove old def so it can work with gazebo
  <link name="base_laser_link" type="laser">
    <inertial>
      <mass value="0.001"/>
      <origin rpy="0 0 0" xyz="0 0 0"/>
      <inertia ixx="0.0001" ixy="0" ixz="0" iyy="0.000001" iyz="0" izz="0.0001"/>
    </inertial>
    <visual>
        <origin xyz="0 0 -0.022" rpy="0 0 0" />
        <geometry>
          <box size="0.05 0.05 0.071" />
        </geometry>
        <material name="Red" />
      </visual>
    <collision>
      <origin rpy="0 0 0" xyz="0 0 -0.022"/>
      <geometry>
        <box size=".05 .05 .071"/>
      </geometry>
    </collision>
  </link>
-->
  <link name="base_laser_link">
    <inertial>
      <origin rpy="0 0 0" xyz="-0.0306228970175641 0.0007091682908278 0.0551974119471302" />
      <mass value="0.00833634573995571" />
      <inertia ixx="1.01866461240801E-06" ixy="-5.88447626567756E-08" ixz="7.83857244757914E-08" iyy="5.10039589974707E-07" iyz="-7.12664289617235E-09" izz="1.28270671527309E-06" />
    </inertial>
    <visual>
      <origin xyz="-0.04 0 -0.012" rpy="0 3.1415 -1.5707"/>
      <geometry>
        <mesh filename="package://turtlebot3_description/meshes/sensors/lds.stl" scale="0.001 0.001 0.001"/> 
      </geometry>
      <material name="dark"/>
    </visual>
    <collision>
      <origin xyz="-0.04 0 -0.012" rpy="0 3.1415 -1.5707"/>
      <geometry>
        <mesh filename="package://turtlebot3_description/meshes/sensors/lds.stl" scale="0.001 0.001 0.001"/> 
      </geometry>
    </collision>
  </link>
  <!-- fixed because there's no transmission -->
  <joint name="rear_castor_joint" type="fixed">
    <origin rpy="0 0 0" xyz="-0.3 0 0"/>
        <!--  Note:
        adding a .01 longer caster for tilt didn't help friction of front wheels
        <origin rpy="0 0 0" xyz="-0.3 0 -.01"/>
        -->
    <parent link="base_link"/>
    <child link="rear_castor_link"/>
    <axis xyz="0 0 0"/>
  </joint>
  <joint name="rear_wheel_joint" type="fixed">
    <origin xyz="0 0 0"/>
    <parent link="rear_castor_link"/>
    <child link="rear_wheel_link"/>
    <axis xyz="0 0 0"/>
  </joint>
  <link name="rear_castor_link">
    <inertial>
      <origin xyz="0 0 .06 "/>
      <mass value=".03" />
      <inertia ixx="0.0001" ixy="0.0" ixz="0.0"
        iyy="0.0001" iyz="0.0" izz="0.0001" />
    </inertial>
    <visual>
      <origin xyz="0 0 .075" rpy="0 0 0"/>
      <geometry>
        <cylinder length="0.105" radius="0.015"/>
        <!-- 
        adding a .01 longer caster for tilt didn't help friction of front wheels
        <origin xyz="0 0 .075" rpy="0 0 0"/>
          <cylinder length="0.125" radius="0.015"/>
        -->
      </geometry>
      <material name="">
        <color rgba="0.792156862745098 0.819607843137255 0.933333333333333 1" />
      </material>
    </visual>
    <collision>
      <origin xyz="0 0 .075" rpy="0 0 0"/>
      <geometry>
        <cylinder length="0.105" radius="0.015"/>
      </geometry>
    </collision>
  </link>
  <link name="rear_wheel_link">
    <inertial>
      <origin xyz="0 0 0" rpy="0 1.5707 1.5707"/>
      <mass value=".0001" />
      <inertia ixx="0.0001" ixy="0.0" ixz="0.0"
        iyy="0.0001" iyz="0.0" izz="0.0001" />
    </inertial>
    <visual>
      <origin xyz="0 0 .015" rpy="0 1.5707 1.5707"/>
      <geometry>
        <sphere radius="0.015" />
      </geometry>
    </visual>
    <collision>
      <origin xyz="0 0 .015" rpy="0 1.5707 1.5707" />
      <geometry>
        <sphere radius="0.015" />
      </geometry>
      <material name="Orange"/>
    </collision>
  </link>
<!--
-->

  <joint name="base_l_wheel_joint" type="continuous">
<!--
    <safety_controller k_velocity="10"/>
-->
    <limit effort="8.85" velocity="17.4" />
    <axis xyz="0 0 -1"/>
    <origin rpy="1.57 0 0" xyz="0 0.19304 0.06191"/>
    <parent link="base_link"/>
    <child link="base_l_wheel_link"/>
<!--
    <dynamics damping="0.7"/>
-->
  </joint>
<macro name="cylinder_inertia" params="m r h">
          <inertia  ixx="${m*(3*r*r+h*h)/12}" ixy = "0" ixz = "0"
                    iyy="${m*(3*r*r+h*h)/12}" iyz = "0"
                    izz="${m*r*r/2}" /> 
</macro>
  <link name="base_l_wheel_link">
    <inertial>
      <!--
       <cylinder_inertia  m=".3531" r="0.06191" h="0.02031" />
       .3531*( 3*.06*.06 + .02*.02) / 12 = .00033
       .3531*.06*.06/2 = .00063558
      -->
      <origin rpy="0 0 0" xyz="0 0 0" />
      <mass value="0.3542" />
      <inertia ixx="0.00033" ixy="0.0" ixz="0.0"
               iyy="0.00033" iyz="0.0"
               izz="0.00063558" />
    </inertial>
    <visual>
      <origin rpy="0 0 0" xyz="0 0 0"/>
      <geometry>
        <cylinder length="0.02032" radius="0.06191"/>
      </geometry>
      <material name="Orange"/>
    </visual>
    <collision>
      <origin rpy="0 0 0" xyz="0 0 0" />
      <geometry>
        <cylinder length="0.02032" radius="0.06191"/>
      </geometry>
    </collision>
  </link>
  <joint name="base_r_wheel_joint" type="continuous">
    <!--
      <safety_controller k_velocity="10"/>
      <axis xyz="0 1 0"/> fetch
     -->
    <limit effort="8.85" velocity="17.4" />
    <axis xyz="0 0 1"/>
    <origin rpy="-1.57 0 0" xyz="0 -0.19304 0.06191"/>
    <parent link="base_link"/>
    <child link="base_r_wheel_link"/>
<!--
    <dynamics damping="0.7"/>
-->
  </joint>
  <link name="base_r_wheel_link">
    <inertial>
      <!-- see base_l_wheel_link for derivation and alternatives -->
      <origin rpy="0 0 0" xyz="0 0 0" />
      <mass value="0.3542" />
      <inertia ixx="0.00033" ixy="0.0" ixz="0.0"
               iyy="0.00033" iyz="0.0"
               izz="0.00063558" />
    </inertial>
    <visual>
      <origin rpy="0 0 0" xyz="0 0 0"/>
      <geometry>
        <cylinder length="0.02032" radius="0.06191"/>
      </geometry>
      <material name="Orange"/>
    </visual>
    <collision>
      <origin rpy="0 0 0" xyz="0 0 0" />
      <geometry>
        <cylinder length="0.02032" radius="0.06191"/>
      </geometry>
    </collision>
  </link>
  <!-- Add Torso Upright -->
  <joint name="torso_joint" type="fixed">
    <origin rpy="0 0 0" xyz="-0.00635 0 0.9184"/>
    <parent link="base_link"/>
    <child link="torso_link"/>
  </joint>
  <link name="torso_link">
    <visual>
      <origin rpy="0 0 0 " xyz="0 0 -0.0762"/>
      <geometry>
        <box size="0.0254 0.0254 1.4224"/>
      </geometry>
      <material name="Grey"/>
    </visual>
    <inertial>
      <!-- 56" of 8020 is 1.2 kg or 2.5 lbs -->
      <mass value="1.2" /> 
      <origin rpy="0 0 0" xyz="-0.0127 0.0127 0.7112" />
      <!-- inertia derivation (see wikipedia)
      Solid cuboid of width w, height h, depth d, and mass m
      <box size="0.0254 0.0254 1.4224"/>
           xx= m(d^2+h^2)/12 = 1.2*(.0254*.0254+1.4224*1.4224)/12 = .2023867
           yy= m(w^2+d^2)/12 = 1.2*(.0254*.0254+.0254*.0254)/12 = .000129
           zz= m(w^2+h^2) == xx = .2023867
           original:
           <inertia ixx="0.2023867" ixy="-0.0" ixz="0.0" iyx="-0.0" iyy="0.000129" iyz="-0.0" izx="0.0" izy="-0.0" izz="0.2023867" />
      -->
      <inertia ixx="0.2023867" ixy="-0.0" ixz="0.0" iyx="-0.0" iyy="0.000129" iyz="-0.0" izx="0.0" izy="-0.0" izz="0.2023867" />
      <collision>
        <origin rpy="0 0 0 " xyz="0 0 -0.0762"/>
        <geometry>
          <box size="0.0254 0.0254 1.4224"/>
        </geometry>
      </collision>
    </inertial>
  </link>
  <joint name="torso_actuator_joint" type="fixed">
    <origin rpy="0 0 0" xyz="0 0 0"/>
    <parent link="torso_link"/>
    <child link="torso_actuator_link"/>
  </joint>
  <link name="torso_actuator_link">
    <!--
      https://www.firgelliauto.com/products/mini-track-actuator
      35 lb dynamic force, 2"/s, 4lbs weight
      use h = 0.635, w=d=.04064
    -->
    <inertial>
      <!-- more accurate mass and intertia:
        <mass value="1.814" />
        xx = m(h^2+d^2)/ 12  yy= m(w^2+d^2)/12, zzz = m(w^2+h^2)/12
        xx == zz = 1.814*(.635*.635+.04064*.04064) = .734446
        yy == 1.814*(.04064*.04064+.04064*.04064) = .005992
        <inertia ixx="0.734446" ixy="-0.0001" ixz="-0.0" iyx="-0.0001" iyy="0.005992" iyz="0.0" izx="-0.0" izy="0.0" izz="0.734446" />
      -->
      <origin rpy="0 0 0" xyz="0.015 0.0127 0.3251" />
      <mass value="1.814" />
      <inertia ixx="0.734446" ixy="-0.0001" ixz="-0.0" iyx="-0.0001" iyy="0.005992" iyz="0.0" izx="-0.0" izy="0.0" izz="0.734446" />
    </inertial>
    <visual>
      <origin rpy="0 0 3.14" xyz="-0.05 -0.0127 -0.560"/>
      <geometry>
        <mesh filename="package://roswell_defs/meshes/FA-35-TR.stl" scale="0.001 0.001 0.001"/>
      </geometry>
      <material name="Grey"/>
    </visual>
    <collision>
      <origin rpy="0 0 0 " xyz="-0.03 0 -0.245"/>
      <geometry>
        <box size="0.03 0.0254 0.650"/>
      </geometry>
    </collision>
  </link>
  <!-- Live joint between torso and arm -->
  <joint name="arm_lift_joint" type="prismatic">
    <axis xyz="0 0 1"/>
    <limit effort="100.0" lower="-0.591" upper="0.0" velocity="0.0508"/>
    <dynamics damping="60.0" />
    <gravity>true</gravity>
    <!--
With real inertia, the linear actuator will drop and then the arm will slowly droop. As the arm droops, the robot will move backwards. This all sucks. As a workaround, fake inertia and mass is used so that the arm is essentially weightless.

Links drop because each PID controller will not apply any force to its joint until the joint has a non-zero velocity. The links will just drop slowly. The only way to prevent this with PID control is to use effort_controllers/JointPositionController, then set joint positions instead of velocities.

To do this, you have to program a interface which accepts the desired velocity from your trajectory planner and integrates the velocity to the desired position. Then you can send this position to the joint position controller. In the real hardware, you are not required to use this interface, you can just directly send the planning result to the robot.

Also, because of the physics simulation, the desired velocity will not be exactly set, which causes a position error between the planned and executed trajectory. 
 
<macro name="default_inertia">
      <inertia ixx="0.001" ixy="0.0" ixz="0.0" iyy="0.001" iyz="0.0" izz="0.001"/>
</macro>
 
<macro name="default_inertia_servos">
      <inertia ixx="0.01" ixy="0.0" ixz="0.0" iyy="0.01" iyz="0.0" izz="0.01"/>
</macro>
 
<macro name="default_limit">
    <limit effort="100.0" lower="-2.62" upper="2.62" velocity="3"/>
</macro>
 
<macro name="default_dynamics">
      <dynamics fricction="0" damping="0" />
</macro>

    <limit effort="450" lower="-0.591" upper="0.0" velocity="0.0508"/>
    <limit effort="150" lower="-0.591" upper="0.0" velocity="0.0508"/>
    <limit effort="450" lower="-0.591" upper="0.0" velocity="0.0508"/>
    <limit effort="450" upper="0.591" lower="0.0" velocity="0.0508"/>
    <limit effort="450" lower="-0.591" upper="0.0" velocity="0.0508"/>
http://answers.ros.org/question/12695/gazebo-freaks-when-joints-hit-limits/
      Force cannot be too high!
      <limit effort="450" lower="-0.591" upper="0.0" velocity="0.0508"/>

      <limit lower="-0.464" upper="0" effort="30" velocity="0.0508"/>
      dynamics damping only makes sense if combined with a bellows like fetch
      Fetch:
        <limit effort="450.0" lower="0" upper="0.4" velocity="0.1" />
        <dynamics damping="100.0" />
      <gazebo reference="arm_lift_joint">
         <stopKd value="1000000.0" />
         <stopKp value="1000000.0" />
      </gazebo>
      <gazebo reference="torso_link">
        <gravity>true</gravity>
      </gazebo>

     also potentially relevant:
http://answers.gazebosim.org/question/7142/strange-behaviour-of-robot-model-when-using-jointsetvelocity-velocityjointinterface/
    -->
    <origin rpy="0 0 0" xyz="0 0 0"/>
    <parent link="torso_link"/>
    <child link="arm_lift_link"/>
  </joint>
  <link name="arm_lift_link">
    <inertial>
      <origin rpy="0 0 0" xyz="-0.07 0 -.36" />
<!--
        <mass value="2.25" />
-->
        <mass value="2.5" />
        <inertia ixx="0.3354" ixy="0.0" ixz="-0.0162" iyx="0.0" iyy="0.3354" iyz="-0.0006" izx="-0.0162" izy="-0.0006" izz="0.0954" />
   <!-- workaround
      <mass value="0.0001" />
      <inertia ixx="0.001" ixy="0.0" ixz="0.0" iyy="0.001" iyz="0.0" izz="0.001" />
   -->
    <!--
      <inertia ixx="0.002" ixy="0" ixz="0" iyx="0.002" iyy="0.001" iyz="0" izx="0.002" izy="0" izz="0.002" />
      from Fetch: Fetch mass value="10.7796" over 22lbs 
        <origin rpy="0 0 0" xyz="-0.0013 -0.0009 0.2935" />
        <mass value="2.25" />
        <inertia ixx="0.3354" ixy="0.0" ixz="-0.0162" iyx="0.0" iyy="0.3354" iyz="-0.0006" izx="-0.0162" izy="-0.0006" izz="0.0954" />
    -->
    </inertial>
  </link>
  <!-- Arm -->
  <joint name="arm_base_joint" type="fixed">
    <origin rpy="0 0 0" xyz="0.0611 0 0"/>
    <parent link="arm_lift_link"/>
    <child link="arm_link"/>
  </joint>
  <link name="arm_link"/>
  <joint name="arm_left_mount_joint" type="fixed">
    <origin rpy="0 0 0" xyz="-0.0611 0.0254 0"/>
    <parent link="arm_link"/>
    <child link="arm_left_mount_link"/>
  </joint>
  <link name="arm_left_mount_link">
    <visual>
      <origin rpy="1.57 3.14 0" xyz="0.01 0 -0.034"/>
      <geometry>
        <mesh filename="package://roswell_defs/meshes/arm_mount.stl" scale="0.001 0.001 0.001"/>
      </geometry>
      <material name="Black"/>
    </visual>
    <inertial>
      <!-- more accurate inertia: -->
        <origin rpy="1.57 3.14 0" xyz="0.01 0 -0.034"/>
        <mass value="0.0798" />
        <inertia ixx="0.002" ixy="0" ixz="0" iyx="0.002" iyy="0.002" iyz="0" izx="0.002" izy="0" izz="0.002" />
    </inertial>
    <collision>
      <origin rpy="0 0 0" xyz="0.03055 -0.00238125 0"/>
      <geometry>
        <box size="0.0865 0.0047625 0.038"/>
      </geometry>
    </collision>
  </link>
  <joint name="arm_right_mount_joint" type="fixed">
    <origin rpy="3.14 0 0" xyz="-0.0611 -0.0254 0"/>
    <parent link="arm_link"/>
    <child link="arm_right_mount_link"/>
  </joint>
  <link name="arm_right_mount_link">
    <visual>
      <origin rpy="1.57 3.14 0" xyz="0.01 0 -0.034"/>
      <geometry>
        <mesh filename="package://roswell_defs/meshes/arm_mount.stl" scale="0.001 0.001 0.001"/>
      </geometry>
      <material name="Black"/>
    </visual>
    <inertial>
        <!-- more accurate inertia: -->
        <mass value="0.0798" />
        <inertia ixx="0.002" ixy="0" ixz="0" iyx="0.002" iyy="0.002" iyz="0" izx="0.002" izy="0" izz="0.002" />
        <origin rpy="1.57 3.14 0" xyz="0.01 0 -0.034"/>
    </inertial>
    <collision>
      <origin rpy="0 0 0" xyz="0.03055 -0.00238125 0"/>
      <geometry>
        <box size="0.0865 0.0047625 0.038"/>
      </geometry>
    </collision>
  </link>
  <joint name="arm_shoulder_pan_servo_joint" type="fixed">
    <origin rpy="0 0 0" xyz="0 0 0"/>
    <parent link="arm_link"/>
    <child link="arm_shoulder_pan_servo_link"/>
  </joint>
  <link name="arm_shoulder_pan_servo_link">
    <visual>
      <origin rpy="0 0 -1.57" xyz=" 0 0 0 "/>
      <geometry>
        <mesh filename="package://roswell_defs/meshes/rx64.stl" scale="1 1 1"/>
      </geometry>
      <material name="Black"/>
    </visual>
    <inertial>
        <origin rpy="0 0 -1.57" xyz=" 0 0 0 "/>
        <!-- mx-64 is .126kg -->
        <mass value="0.169374038216602" />
        <inertia ixx="0.00331159128762117" ixy="-8.9230964321455E-18" ixz="-5.38622201018293E-08" iyy="0.00174447292786627" iyz="-8.06964979976371E-17" izz="0.00169417568121457" />
    </inertial>
    <collision>
      <origin rpy="0 0 0" xyz="-0.01755 0.0 0"/>
      <geometry>
        <box size="0.0611 0.0420 0.0470"/>
      </geometry>
    </collision>
  </link>
  <joint name="arm_shoulder_pan_joint" type="revolute">
    <origin rpy="0 0 0" xyz="0 0 0.0235"/>
    <axis xyz="0 0 1"/>
    <dynamics damping="7.0" />
    <limit effort="100.0" lower="-1.57" upper="1.57" velocity="0.524"/>
    <!--
      <limit effort="10" velocity="5.6548668" lower="-2.6179939" upper="2.6179939" />
    -->
    <parent link="arm_shoulder_pan_servo_link"/>
    <child link="arm_shoulder_pan_link"/>
  </joint>
  <link name="arm_shoulder_pan_link">
    <inertial>
      <!-- more accurate inertial:
        <origin rpy="0 0 0" xyz="0.0191320000286228 -1.67219873481315E-16 -0.134861625443387" />
      -->
        <origin rpy="1.57 0 0" xyz=" 0 0 0 "/>
        <mass value="0.0798" />
        <inertia ixx="0.00331159128762117" ixy="-8.9230964321455E-18" ixz="-5.38622201018293E-08" iyy="0.00174447292786627" iyz="-8.06964979976371E-17" izz="0.00169417568121457" />
    </inertial>
    <visual>
      <origin rpy="1.57 0 0" xyz=" 0 0 0 "/>
      <geometry>
        <mesh filename="package://roswell_defs/meshes/rx64-side-bracket.stl" scale="1 1 1"/>
      </geometry>
      <material name="Grey"/>
    </visual>
    <collision>
      <origin rpy="0 0 0" xyz="0.000 0 0.005"/>
      <geometry>
        <box size="0.037 0.037 0.010"/>
      </geometry>
    </collision>
  </link>
  <joint name="arm_shoulder_lift_servo_joint" type="fixed">
    <origin rpy="0 -1.57 0" xyz="0 0 0.0526"/>
    <parent link="arm_shoulder_pan_link"/>
    <child link="arm_shoulder_lift_servo_link"/>
  </joint>
  <link name="arm_shoulder_lift_servo_link">
    <visual>
      <origin rpy="1.57 1.57 0" xyz=" 0 0 0 "/>
      <geometry>
        <mesh filename="package://roswell_defs/meshes/rx64.stl" scale="1 1 1"/>
      </geometry>
      <material name="Black"/>
    </visual>
    <inertial>
      <!-- more accurate inertial: -->
        <origin rpy="1.57 1.57 0" xyz=" 0 0 0 "/>
        <mass value="0.169374038216602" />
        <inertia ixx="0.00331159128762117" ixy="-8.9230964321455E-18" ixz="-5.38622201018293E-08" iyy="0.00174447292786627" iyz="-8.06964979976371E-17" izz="0.00169417568121457" />
    </inertial>
    <collision>
      <origin rpy="0 0 0" xyz="-0.01755 0 0"/>
      <geometry>
        <box size="0.0611 0.0470 0.0420"/>
      </geometry>
    </collision>
  </link>
  <joint name="arm_shoulder_lift_joint" type="revolute">
    <origin rpy="0 0 0" xyz="0 0 0"/>
    <axis xyz="0 1 0"/>
    <dynamics damping="1.0" />
    <limit effort="131.76" lower="-1.221" upper="1.518" velocity="1.454" />
    <!--
      <limit effort="550" velocity="5.6548668" lower="-1.77" upper="1.317" />
      <dynamics friction="0" damping="0" />
      <limit effort="150" lower="-1.77" upper="1.317" velocity="0.524"/>
      <limit effort="30" lower="-1.77" upper="1.317" velocity="0.524"/>
    -->
    <parent link="arm_shoulder_lift_servo_link"/>
    <child link="arm_shoulder_lift_link"/>
  </joint>
  <link name="arm_shoulder_lift_link">
    <inertial>
      <!-- more accurate inertial: -->
        <origin rpy="-1.57 0 0" xyz="0 0 0"/>
        <mass value="0.0798" />
        <inertia ixx="0.00331159128762117" ixy="-8.9230964321455E-18" ixz="-5.38622201018293E-08" iyy="0.00174447292786627" iyz="-8.06964979976371E-17" izz="0.00169417568121457" />
    </inertial>
    <visual>
      <origin rpy="-1.57 0 0" xyz="0 0 0"/>
      <geometry>
        <mesh filename="package://roswell_defs/meshes/sixdof_bracket1.stl" scale="0.001 0.001 0.001"/>
      </geometry>
      <material name="Black"/>
    </visual>
    <collision>
      <origin rpy="0 0 0" xyz="0.0381 0.0 0.0"/>
      <geometry>
        <box size="0.0762 0.053 0.044"/>
      </geometry>
    </collision>
  </link>
  <joint name="arm_upperarm_roll_servo_joint" type="fixed">
    <origin rpy="1.57 1.57 0" xyz="0.0712978 0 0"/>
    <parent link="arm_shoulder_lift_link"/>
    <child link="arm_upperarm_roll_servo_link"/>
  </joint>
  <link name="arm_upperarm_roll_servo_link">
    <inertial>
      <!-- more accurate inertial: -->
        <origin rpy="1.57 1.57 0" xyz=" 0 0 0 "/>
        <mass value="0.169374038216602" />
        <inertia ixx="0.00331159128762117" ixy="-8.9230964321455E-18" ixz="-5.38622201018293E-08" iyy="0.00174447292786627" iyz="-8.06964979976371E-17" izz="0.00169417568121457" />
    </inertial>
    <visual>
      <origin rpy="1.57 1.57 0" xyz=" 0 0 0 "/>
      <geometry>
        <mesh filename="package://roswell_defs/meshes/rx64.stl" scale="1 1 1"/>
      </geometry>
      <material name="Black"/>
    </visual>
    <collision>
      <origin rpy="0 0 0" xyz="-0.01755 0 0"/>
      <geometry>
        <box size="0.0611 0.0470 0.0420"/>
      </geometry>
    </collision>
  </link>
  <joint name="arm_upperarm_roll_joint" type="revolute">
    <origin rpy="-1.57 0 1.57" xyz="0 0 0"/>
    <axis xyz="1 0 0"/>
    <!--
      <dynamics damping="7.0" />
    <limit effort="150.0" lower="-2" upper="2" velocity="0.524"/>
    -->
    <dynamics damping="5.0" />
    <limit effort="76.94" velocity="1.571" lower="-2" upper="2" />
    <!-- was effort="30" -->
    <parent link="arm_upperarm_roll_servo_link"/>
    <child link="arm_upperarm_roll_link"/>
  </joint>
  <link name="arm_upperarm_roll_link">
    <inertial>
      <!-- more accurate inertial: -->
        <origin rpy="-1.57 0 3.14" xyz="0.0869955 0 0"/>
        <mass value="0.0798" />
        <inertia ixx="0.00331159128762117" ixy="-8.9230964321455E-18" ixz="-5.38622201018293E-08" iyy="0.00174447292786627" iyz="-8.06964979976371E-17" izz="0.00169417568121457" />
    </inertial>
    <visual>
      <origin rpy="-1.57 0 3.14" xyz="0.0869955 0 0"/>
      <geometry>
        <mesh filename="package://roswell_defs/meshes/sixdof_bracket2.stl" scale="0.001 0.001 0.001"/>
      </geometry>
      <material name="Black"/>
    </visual>
    <collision>
      <origin rpy="0 0 0" xyz="0.0381 0.0 0.0"/>
      <geometry>
        <box size="0.0762 0.053 0.044"/>
      </geometry>
    </collision>
  </link>
  <joint name="arm_elbow_flex_joint" type="revolute">
    <origin rpy="0 0 0" xyz="0.0869955 0 0"/>
    <axis xyz="0 1 0"/>
    <dynamics damping="7.5" /> 
    <limit effort="131.76" lower="-1.57" upper="2.251" velocity="0.524" />
<!--
    <dynamics damping="7.5" /> 
    <limit effort="66.18" lower="-1.57" upper="2.251" velocity="1.521" />
    <limit effort="131.76" lower="-1.221" upper="1.518" velocity="1.454" />
    <limit effort="550" lower="-1.57" upper="2.617" velocity="0.524"/>
    <dynamics damping="7.0" />
    <limit effort="10" lower="-1.57" upper="2.617" velocity="0.524"/>
-->
    <parent link="arm_upperarm_roll_link"/>
    <child link="arm_elbow_flex_link"/>
  </joint>
  <link name="arm_elbow_flex_link">
    <inertial>
      <!-- more accurate inertial: -->
      <origin rpy="1.57 -1.57 0" xyz=" 0 0 0 "/>
      <mass value="0.169374038216602" />
      <inertia ixx="0.00331159128762117" ixy="-8.9230964321455E-18" ixz="-5.38622201018293E-08" iyy="0.00174447292786627" iyz="-8.06964979976371E-17" izz="0.00169417568121457" />
    </inertial>
    <visual>
      <origin rpy="1.57 -1.57 0" xyz=" 0 0 0 "/>
      <geometry>
        <mesh filename="package://roswell_defs/meshes/rx64.stl" scale="1 1 1"/>
      </geometry>
      <material name="Black"/>
    </visual>
    <collision>
      <origin rpy="0 0 0" xyz="0.01755 0 0"/>
      <geometry>
        <box size="0.0611 0.0470 0.0420"/>
      </geometry>
    </collision>
  </link>
  <joint name="arm_forearm_fixed_joint" type="fixed">
    <origin rpy="0 0 0" xyz="0 0 0"/>
    <parent link="arm_elbow_flex_link"/>
    <child link="arm_forearm_link"/>
  </joint>
  <link name="arm_forearm_link">
    <inertial>
        <!-- more accurate inertial: -->
        <mass value="0.169374038216602" />
        <origin rpy="-1.57 0 0" xyz="0 0 0"/>
        <inertia ixx="0.00331159128762117" ixy="-8.9230964321455E-18" ixz="-5.38622201018293E-08" iyy="0.00174447292786627" iyz="-8.06964979976371E-17" izz="0.00169417568121457" />
    </inertial>
    <visual>
      <origin rpy="-1.57 0 0" xyz="0 0 0"/>
      <geometry>
        <mesh filename="package://roswell_defs/meshes/arm_mx64_forearm.stl" scale="1 1 1"/>
      </geometry>
      <material name="Black"/>
    </visual>
    <collision>
      <origin rpy="0 0 0" xyz="0.0625 0.0 0.0"/>
      <geometry>
        <box size="0.03 0.053 0.044"/>
      </geometry>
    </collision>
  </link>
  <joint name="arm_wrist_flex_servo_joint" type="fixed">
    <origin rpy="0 0 0" xyz="0.125 0 0"/>
    <parent link="arm_forearm_link"/>
    <child link="arm_wrist_flex_servo_link"/>
  </joint>
  <link name="arm_wrist_flex_servo_link">
    <inertial>
        <mass value="0.169374038216602" />
        <origin rpy="1.57 1.57 0" xyz=" 0 0 0 "/>
        <inertia ixx="0.00331159128762117" ixy="-8.9230964321455E-18" ixz="-5.38622201018293E-08" iyy="0.00174447292786627" iyz="-8.06964979976371E-17" izz="0.00169417568121457" />
    </inertial>
    <visual>
      <origin rpy="1.57 1.57 0" xyz=" 0 0 0 "/>
      <geometry>
        <mesh filename="package://roswell_defs/meshes/rx64.stl" scale="1 1 1"/>
      </geometry>
      <material name="Black"/>
    </visual>
    <collision>
      <origin rpy="0 0 0" xyz="-0.01755 0 0"/>
      <geometry>
        <box size="0.0611 0.0470 0.0420"/>
      </geometry>
    </collision>
  </link>
  <joint name="arm_wrist_flex_joint" type="revolute">
    <origin rpy="0 0 0" xyz="0 0 0.0"/>
    <axis xyz="0 1 0"/>
    <dynamics damping="7.0" />
<!--
    <limit effort="80" lower="-1.57" upper="1.57" velocity="0.785"/>
-->
    <limit effort="30" lower="-1.57" upper="1.57" velocity="0.785"/>
    <parent link="arm_wrist_flex_servo_link"/>
    <child link="arm_wrist_flex_link"/>
  </joint>
  <link name="arm_wrist_flex_link">
    <inertial>
      <!-- more accurate inertial for ax-64 :
      <inertia ixx="0.002" ixy="0" ixz="0" iyx="0.002" iyy="0.002" iyz="0" izx="0.002" izy="0" izz="0.002" />
      -->
      <origin rpy="0 0 -1.57" xyz="0 0 0"/>
      <mass value="0.169374038216602" />
      <inertia ixx="0.00331159128762117" ixy="-8.9230964321455E-18" ixz="-5.38622201018293E-08" iyy="0.00174447292786627" iyz="-8.06964979976371E-17" izz="0.00169417568121457" />

      <origin xyz="0 0 0"/>
    </inertial>
    <visual>
      <origin rpy="0 0 -1.57" xyz="0 0 0"/>
      <geometry>
        <mesh filename="package://roswell_defs/meshes/rx64-hinge-bracket.stl" scale="1 1 1"/>
      </geometry>
      <material name="Grey"/>
    </visual>
    <collision>
      <origin rpy="0 0 0" xyz="0.015 0.0 0.0"/>
      <geometry>
        <box size="0.030 0.056 0.031"/>
      </geometry>
    </collision>
  </link>
  <joint name="arm_wrist_roll_joint" type="revolute">
    <axis xyz="1 0 0"/>
    <!--
    <dynamics damping="7.0" />
    -->
    <limit effort="30" lower="-2.617" upper="2.617" velocity="0.785"/>
    <origin rpy="0 0 0" xyz="0.041 0 0"/>
    <parent link="arm_wrist_flex_link"/>
    <child link="arm_wrist_roll_link"/>
  </joint>
  <link name="arm_wrist_roll_link">
    <!-- more accurate inertial based on ax-12: -->
    <inertial>
      <mass value="0.0535"/> 
      <origin rpy="0 0 1.57" xyz="0.01905 0 0"/>
      <inertia ixx="0.002" ixy="0" ixz="0" iyx="0.002" iyy="0.002" iyz="0" izx="0.002" izy="0" izz="0.002" />
    </inertial>
    <visual>
      <!-- todo: Roswell has slightly diff connectors than Maxwell -->
      <origin rpy="0 0 1.57" xyz="0.01905 0 0"/>
      <geometry>
        <mesh filename="package://roswell_defs/meshes/ax12.stl" scale="0.001 0.001 0.001"/>
      </geometry>
      <material name="Black"/>
    </visual>
    <collision>
      <origin rpy="0 0 1.57" xyz="0.01905 0 0"/>
<!--
      <origin rpy="0 0 0" xyz="0.02 0.0 -0.0133 "/>
-->
      <geometry>
        <box size="0.040 0.032 0.0501"/>
      </geometry>
    </collision>
  </link>
  <!-- Gripper -->
  <joint name="gripper_F6_1_joint" type="fixed">
    <origin rpy="0 0 0" xyz="0.01905 0.017 -0.014"/>
    <parent link="arm_wrist_roll_link"/>
    <child link="gripper_F6_1_link"/>
  </joint>
  <link name="gripper_F6_1_link">
    <inertial>
      <mass value="0.00001"/>
      <origin xyz="0 0 0"/>
      <inertia ixx="1.0" ixy="0.0" ixz="0.0" iyy="1.0" iyz="0.0" izz="1.0"/>
    </inertial>
    <visual>
      <origin rpy="3.14 0 0" xyz=" 0 0 0 "/>
      <geometry>
        <mesh filename="package://roswell_defs/meshes/F6.stl" scale="1 1 1"/>
      </geometry>
      <material name="Black"/>
    </visual>
    <collision>
      <origin rpy="0 0 0" xyz="0.001 0.0 0.0"/>
      <geometry>
        <box size="0.04 0.005 0.024"/>
      </geometry>
    </collision>
  </link>
  <joint name="gripper_F6_2_joint" type="fixed">
    <origin rpy="3.14 3.14 0" xyz="0.008 0.004 0"/>
    <parent link="gripper_F6_1_link"/>
    <child link="gripper_F6_2_link"/>
  </joint>
  <link name="gripper_F6_2_link">
    <inertial>
      <mass value="0.00001"/>
      <origin xyz="0 0 0"/>
      <inertia ixx="1.0" ixy="0.0" ixz="0.0" iyy="1.0" iyz="0.0" izz="1.0"/>
    </inertial>
    <visual>
      <origin rpy="3.14 0 0" xyz=" 0 0 0 "/>
      <geometry>
        <mesh filename="package://roswell_defs/meshes/F6.stl" scale="1 1 1"/>
      </geometry>
      <material name="Black"/>
    </visual>
    <collision>
      <origin rpy="0 0 0" xyz="0.001 0.0 0.0"/>
      <geometry>
        <box size="0.04 0.005 0.024"/>
      </geometry>
    </collision>
  </link>
  <joint name="gripper_F6_3_joint" type="fixed">
    <origin rpy="3.14 0 0" xyz="0.01905 -0.017 -0.014"/>
    <parent link="arm_wrist_roll_link"/>
    <child link="gripper_F6_3_link"/>
  </joint>
  <link name="gripper_F6_3_link">
    <inertial>
      <mass value="0.00001"/>
      <origin xyz="0 0 0"/>
      <inertia ixx="1.0" ixy="0.0" ixz="0.0" iyy="1.0" iyz="0.0" izz="1.0"/>
    </inertial>
    <visual>
      <origin rpy="3.14 0 0" xyz=" 0 0 0 "/>
      <geometry>
        <mesh filename="package://roswell_defs/meshes/F6.stl" scale="1 1 1"/>
      </geometry>
      <material name="Black"/>
    </visual>
    <collision>
      <origin rpy="0 0 0" xyz="0.001 0.0 0.0"/>
      <geometry>
        <box size="0.04 0.005 0.024"/>
      </geometry>
    </collision>
  </link>
  <joint name="gripper_F6_4_joint" type="fixed">
    <origin rpy="0 0 3.14" xyz="0.008 0.004 0"/>
    <parent link="gripper_F6_3_link"/>
    <child link="gripper_F6_4_link"/>
  </joint>
  <link name="gripper_F6_4_link">
    <inertial>
      <mass value="0.00001"/>
      <origin xyz="0 0 0"/>
      <inertia ixx="1.0" ixy="0.0" ixz="0.0" iyy="1.0" iyz="0.0" izz="1.0"/>
    </inertial>
    <visual>
      <origin rpy="3.14 0 0" xyz=" 0 0 0 "/>
      <geometry>
        <mesh filename="package://roswell_defs/meshes/F6.stl" scale="1 1 1"/>
      </geometry>
      <material name="Black"/>
    </visual>
    <collision>
      <origin rpy="0 0 0" xyz="0.001 0.0 0.0"/>
      <geometry>
        <box size="0.04 0.005 0.024"/>
      </geometry>
    </collision>
  </link>
  <joint name="left_gripper_mount_joint" type="fixed">
    <origin rpy="1.57 0 1.57" xyz="-0.018 0.005 0"/>
    <parent link="gripper_F6_2_link"/>
    <child link="left_gripper_mount_link"/>
  </joint>
  <link name="left_gripper_mount_link">
    <inertial>
      <mass value="0.00001"/>
      <origin xyz="0 0 0"/>
      <inertia ixx="1.0" ixy="0.0" ixz="0.0" iyy="1.0" iyz="0.0" izz="1.0"/>
    </inertial>
    <visual>
      <origin rpy="0 0 0" xyz=" 0 0 0 "/>
      <geometry>
        <mesh filename="package://roswell_defs/meshes/F3.stl" scale="0.001 0.001 0.001"/>
      </geometry>
      <material name="Black"/>
    </visual>
    <collision>
      <origin rpy="0 0 0" xyz="0.0 0.0 -0.0045"/>
      <geometry>
        <box size="0.025 0.038 0.009"/>
      </geometry>
    </collision>
  </link>
  <joint name="right_gripper_mount_joint" type="fixed">
    <origin rpy="1.57 0 1.57" xyz="-0.018 0.005 0"/>
    <parent link="gripper_F6_4_link"/>
    <child link="right_gripper_mount_link"/>
  </joint>
  <link name="right_gripper_mount_link">
    <inertial>
      <mass value="0.00001"/>
      <origin xyz="0 0 0"/>
      <inertia ixx="1.0" ixy="0.0" ixz="0.0" iyy="1.0" iyz="0.0" izz="1.0"/>
    </inertial>
    <visual>
      <origin rpy="0 0 0" xyz=" 0 0 0 "/>
      <geometry>
        <mesh filename="package://roswell_defs/meshes/F3.stl" scale="0.001 0.001 0.001"/>
      </geometry>
      <material name="Black"/>
    </visual>
    <collision>
      <origin rpy="0 0 0" xyz="0.0 0.0 -0.0045"/>
      <geometry>
        <box size="0.025 0.038 0.009"/>
      </geometry>
    </collision>
  </link>
  <joint name="left_gripper_servo_joint" type="fixed">
    <origin rpy="-1.57 1.57 0" xyz="0 0 -0.042"/>
    <parent link="left_gripper_mount_link"/>
    <child link="left_gripper_servo_link"/>
  </joint>
  <link name="left_gripper_servo_link">
    <inertial>
<!-- workaround
      <mass value="0.00001"/>
      <origin xyz="0 0 0"/>
      <inertia ixx="1.0" ixy="0.0" ixz="0.0" iyy="1.0" iyz="0.0" izz="1.0"/>
-->
<!-- more accurate inertial for ax-12:
-->
      <mass value="0.0535"/> 
      <origin xyz="0 0 0"/>
      <inertia ixx="0.002" ixy="0" ixz="0" iyx="0.002" iyy="0.002" iyz="0" izx="0.002" izy="0" izz="0.002" />
    </inertial>
    <visual>
      <origin rpy="1.57 0 1.57" xyz=" 0 0 0 "/>
      <geometry>
        <mesh filename="package://roswell_defs/meshes/ax12.stl" scale="0.001 0.001 0.001"/>
      </geometry>
      <material name="Black"/>
    </visual>
    <collision>
      <origin rpy="0 0 0" xyz="-0.01345 0.0 0.0"/>
      <geometry>
        <box size="0.0501 0.032 0.040"/>
      </geometry>
    </collision>
  </link>
  <joint name="right_gripper_servo_joint" type="fixed">
    <origin rpy="1.57 1.57 0" xyz="0 0 -0.042"/>
    <parent link="right_gripper_mount_link"/>
    <child link="right_gripper_servo_link"/>
  </joint>
  <link name="right_gripper_servo_link">
<!-- workaround
    <inertial>
      <mass value="0.00001"/>
      <origin xyz="0 0 0"/>
      <inertia ixx="1.0" ixy="0.0" ixz="0.0" iyy="1.0" iyz="0.0" izz="1.0"/>
    </inertial>
-->
<!-- more accurate inertial for ax-12:
-->
    <inertial>
      <mass value="0.0535"/> 
      <origin xyz="0 0 0"/>
      <inertia ixx="0.002" ixy="0" ixz="0" iyx="0.002" iyy="0.002" iyz="0" izx="0.002" izy="0" izz="0.002" />
    </inertial>
    <visual>
      <origin rpy="1.57 0 1.57" xyz=" 0 0 0 "/>
      <geometry>
        <mesh filename="package://roswell_defs/meshes/ax12.stl" scale="0.001 0.001 0.001"/>
      </geometry>
      <material name="Black"/>
    </visual>
    <collision>
      <origin rpy="0 0 0" xyz="-0.01345 0.0 0.0"/>
      <geometry>
        <box size="0.0501 0.032 0.040"/>
      </geometry>
    </collision>
  </link>
  <joint name="l_gripper_joint" type="revolute">
    <origin rpy="3.14 0 1.57" xyz="0 0 0"/>
    <axis xyz="0 0 1"/>
    <!--
    <dynamics damping="7.0" />
    -->
    <limit effort="30" lower="-1.57" upper="1.57" velocity="0.5"/>
    <parent link="left_gripper_servo_link"/>
    <child link="l_gripper_link"/>
  </joint>
  <link name="l_gripper_link">
    <inertial>
      <mass value="0.00001"/>
      <origin xyz="0 0 0"/>
      <inertia ixx="1.0" ixy="0.0" ixz="0.0" iyy="1.0" iyz="0.0" izz="1.0"/>
    </inertial>
<!-- more accurate inertial for ax-12:
    <inertial>
      <mass value="0.0535"/> 
      <origin xyz="0 0 0"/>
      <inertia ixx="0.002" ixy="0" ixz="0" iyx="0.002" iyy="0.002" iyz="0" izx="0.002" izy="0" izz="0.002" />
    </inertial>
-->
    <visual>
      <origin rpy="3.14 0 0" xyz=" 0 0 0 "/>
      <geometry>
        <mesh filename="package://roswell_defs/meshes/F1.stl" scale="1 1 1"/>
      </geometry>
      <material name="Orange"/>
    </visual>
    <collision>
      <origin rpy="0 0 .8" xyz="0.01 0.008 0.0"/>
      <geometry>
        <box size="0.04 0.028 0.046"/>
      </geometry>
    </collision>
  </link>
  <joint name="r_gripper_joint" type="revolute">
    <inertial>
      <mass value="0.00001"/>
      <origin xyz="0 0 0"/>
      <inertia ixx="1.0" ixy="0.0" ixz="0.0" iyy="1.0" iyz="0.0" izz="1.0"/>
    </inertial>
<!-- more accurate inertial for ax-12:
    <inertial>
      <mass value="0.0535"/> 
      <origin xyz="0 0 0"/>
      <inertia ixx="0.002" ixy="0" ixz="0" iyx="0.002" iyy="0.002" iyz="0" izx="0.002" izy="0" izz="0.002" />
    </inertial>
-->
    <origin rpy="0 0 -1.57" xyz="0 0 0"/>
    <axis xyz="0 0 1"/>
    <dynamics damping="7.0" />
    <limit effort="30" lower="-1.57" upper="1.57" velocity="0.5"/>
    <parent link="right_gripper_servo_link"/>
    <child link="r_gripper_link"/>
  </joint>
  <link name="r_gripper_link">
    <inertial>
      <mass value="0.00001"/>
      <origin xyz="0 0 0"/>
      <inertia ixx="1.0" ixy="0.0" ixz="0.0" iyy="1.0" iyz="0.0" izz="1.0"/>
    </inertial>
    <visual>
      <origin rpy="3.14 0 0" xyz=" 0 0 0 "/>
      <geometry>
        <mesh filename="package://roswell_defs/meshes/F1.stl" scale="1 1 1"/>
      </geometry>
      <material name="Orange"/>
    </visual>
    <collision>
      <origin rpy="0 0 .8" xyz="0.01 0.008 0.0"/>
      <geometry>
        <box size="0.04 0.028 0.046"/>
      </geometry>
    </collision>
  </link>
  <joint name="left_gripper_F9_joint" type="fixed">
    <origin rpy="0 3.14 0" xyz="0.0155 0.038 0"/>
    <parent link="l_gripper_link"/>
    <child link="left_gripper_F9_link"/>
  </joint>
  <link name="left_gripper_F9_link">
    <inertial>
      <mass value="0.00001"/>
      <origin xyz="0 0 0"/>
      <inertia ixx="1.0" ixy="0.0" ixz="0.0" iyy="1.0" iyz="0.0" izz="1.0"/>
    </inertial>
    <visual>
      <origin rpy="0 0 0" xyz="0 0 0"/>
      <geometry>
        <mesh filename="package://roswell_defs/meshes/F9.stl" scale="1 1 1"/>
      </geometry>
      <material name="Black"/>
    </visual>
    <collision>
      <origin rpy="0 0 0" xyz="-0.008 0.0 0.0"/>
      <geometry>
        <box size="0.008 0.03 0.024"/>
      </geometry>
    </collision>
  </link>
  <joint name="right_gripper_F9_joint" type="fixed">
    <origin rpy="0 3.14 0" xyz="0.0155 0.038 0"/>
    <parent link="r_gripper_link"/>
    <child link="right_gripper_F9_link"/>
  </joint>
  <link name="right_gripper_F9_link">
    <inertial>
      <mass value="0.00001"/>
      <origin xyz="0 0 0"/>
      <inertia ixx="1.0" ixy="0.0" ixz="0.0" iyy="1.0" iyz="0.0" izz="1.0"/>
    </inertial>
    <visual>
      <origin rpy="0 0 0" xyz="0 0 0"/>
      <geometry>
        <mesh filename="package://roswell_defs/meshes/F9.stl" scale="1 1 1"/>
      </geometry>
      <material name="Black"/>
    </visual>
    <collision>
      <origin rpy="0 0 0" xyz="-0.008 0.0 0.0"/>
      <geometry>
        <box size="0.008 0.03 0.024"/>
      </geometry>
    </collision>
  </link>
  <joint name="left_gripper_finger_joint" type="fixed">
    <origin rpy="0 0 0" xyz="0 -0.013 0 "/>
    <parent link="left_gripper_F9_link"/>
    <child link="left_gripper_finger_link"/>
  </joint>
  <link name="left_gripper_finger_link">
    <inertial>
      <mass value="0.00001"/>
      <origin xyz="0 0 0"/>
      <inertia ixx="1.0" ixy="0.0" ixz="0.0" iyy="1.0" iyz="0.0" izz="1.0"/>
    </inertial>
    <visual>
      <origin rpy="0 0 0" xyz="0 0 0"/>
      <geometry>
        <mesh filename="package://roswell_defs/meshes/F11.stl" scale="1 1 1"/>
      </geometry>
      <material name="Grey"/>
    </visual>
    <collision>
      <origin rpy="0 0 0" xyz="-0.008 0.025 0.0"/>
      <geometry>
        <box size="0.009 0.06 0.028"/>
      </geometry>
    </collision>
  </link>
  <joint name="right_gripper_finger_joint" type="fixed">
    <origin rpy="0 0 0" xyz="0 -0.013 0"/>
    <parent link="right_gripper_F9_link"/>
    <child link="right_gripper_finger_link"/>
  </joint>
  <link name="right_gripper_finger_link">
    <inertial>
      <mass value="0.00001"/>
      <origin xyz="0 0 0"/>
      <inertia ixx="1.0" ixy="0.0" ixz="0.0" iyy="1.0" iyz="0.0" izz="1.0"/>
    </inertial>
    <visual>
      <origin rpy="0 0 0" xyz="0 0 0"/>
      <geometry>
        <mesh filename="package://roswell_defs/meshes/F11.stl" scale="1 1 1"/>
      </geometry>
      <material name="Grey"/>
    </visual>
    <collision>
      <origin rpy="0 0 0" xyz="-0.008 0.025 0.0"/>
      <geometry>
        <box size="0.009 0.06 0.028"/>
      </geometry>
    </collision>
  </link>
  <!-- Head -->
  <joint name="head_joint" type="fixed">
    <origin rpy="0 0 0" xyz="0 0 0.635"/>
    <parent link="torso_link"/>
    <child link="head_link"/>
  </joint>
  <link name="head_link"/>
  <joint name="head_left_mount_joint" type="fixed">
    <origin rpy="0 0 0" xyz="0 0.01905 0"/>
    <parent link="head_link"/>
    <child link="head_left_mount_link"/>
  </joint>
  <link name="head_left_mount_link">
    <inertial>
      <mass value="0.00001"/>
      <origin xyz="0 0 0"/>
      <inertia ixx="1.0" ixy="0.0" ixz="0.0" iyy="1.0" iyz="0.0" izz="1.0"/>
    </inertial>
    <visual>
      <origin rpy="-1.57 3.14 0" xyz="0 0 0"/>
      <geometry>
        <mesh filename="package://roswell_defs/meshes/head_mount.stl" scale="1 1 1"/>
      </geometry>
      <material name="Black"/>
    </visual>
    <collision>
      <origin rpy="0 1.57 0" xyz="0 0 0"/>
      <geometry>
        <box size="0.0865 0.0047625 0.038"/>
      </geometry>
    </collision>
  </link>
  <joint name="head_right_mount_joint" type="fixed">
    <origin rpy="0 0 0" xyz="0 -0.022225 0"/>
    <parent link="head_link"/>
    <child link="head_right_mount_link"/>
  </joint>
  <link name="head_right_mount_link">
    <inertial>
      <mass value="0.00001"/>
      <origin xyz="0 0 0"/>
      <inertia ixx="1.0" ixy="0.0" ixz="0.0" iyy="1.0" iyz="0.0" izz="1.0"/>
    </inertial>
    <visual>
      <origin rpy="-1.57 3.14 0" xyz="0 0 0"/>
      <geometry>
        <mesh filename="package://roswell_defs/meshes/head_mount.stl" scale="1 1 1"/>
      </geometry>
      <material name="Black"/>
    </visual>
    <collision>
      <origin rpy="0 1.57 0" xyz="0 0 0"/>
      <geometry>
        <box size="0.0865 0.0047625 0.038"/>
      </geometry>
    </collision>
  </link>
  <joint name="head_pan_servo_joint" type="fixed">
    <origin rpy="0 0 0" xyz="0.010 0 0.0254"/>
    <parent link="head_link"/>
    <child link="head_pan_servo_link"/>
  </joint>
  <link name="head_pan_servo_link">
    <inertial>
      <mass value="0.0535"/> <!-- ax-12 -->
      <origin xyz="0 0 0"/>
      <inertia ixx="1.0" ixy="0.0" ixz="0.0" iyy="1.0" iyz="0.0" izz="1.0"/>
    </inertial>
    <visual>
      <origin rpy="1.57 0 1.57" xyz=" 0 0 0 "/>
      <geometry>
        <mesh filename="package://roswell_defs/meshes/ax12.stl" scale="0.001 0.001 0.001"/>
      </geometry>
      <material name="Black"/>
    </visual>
    <collision>
      <origin rpy="0 0 0" xyz="-0.01345 0.0 0.0"/>
      <geometry>
        <box size="0.0501 0.032 0.040"/>
      </geometry>
    </collision>
  </link>
  <joint name="head_pan_joint" type="revolute">
    <origin rpy="0 0 0" xyz="0 0 0.019"/>
    <axis xyz="0 0 1"/>
    <limit effort="30" lower="-2.617" upper="2.617" velocity="1.0"/>
    <parent link="head_pan_servo_link"/>
    <child link="head_pan_link"/>
  </joint>
  <link name="head_pan_link">
    <inertial>
      <mass value="0.0535"/> 
      <origin xyz="0 0 0"/>
      <inertia ixx="1.0" ixy="0.0" ixz="0.0" iyy="1.0" iyz="0.0" izz="1.0"/>
    </inertial>
    <visual>
      <origin rpy="3.14 0 0" xyz=" 0 0 0 "/>
      <geometry>
        <mesh filename="package://roswell_defs/meshes/F3.stl" scale="0.001 0.001 0.001"/>
      </geometry>
      <material name="Orange"/>
    </visual>
    <collision>
      <origin rpy="0 0 0" xyz="0.0 0.0 0.0045"/>
      <geometry>
        <box size="0.025 0.038 0.009"/>
      </geometry>
    </collision>
  </link>
  <joint name="head_tilt_left_side_joint" type="fixed">
    <origin rpy="1.57 0 0" xyz="-0.015 -0.019 0"/>
    <parent link="head_pan_servo_link"/>
    <child link="head_tilt_left_side_link"/>
  </joint>
  <link name="head_tilt_left_side_link">
    <inertial>
      <mass value="0.00001"/>
      <origin xyz="0 0 0"/>
      <inertia ixx="1.0" ixy="0.0" ixz="0.0" iyy="1.0" iyz="0.0" izz="1.0"/>
    </inertial>
    <visual>
      <origin rpy="0 0 0" xyz=" 0 0 0 "/>
      <geometry>
        <mesh filename="package://roswell_defs/meshes/F3.stl" scale="0.001 0.001 0.001"/>
      </geometry>
      <material name="Black"/>
    </visual>
    <collision>
      <origin rpy="0 0 0" xyz="0.0 0.0 -0.0045"/>
      <geometry>
        <box size="0.025 0.038 0.009"/>
      </geometry>
    </collision>
  </link>
  <joint name="head_tilt_right_side_joint" type="fixed">
    <origin rpy="-1.57079632679 0 0" xyz="-0.015 0.019 0"/>
    <parent link="head_pan_servo_link"/>
    <child link="head_tilt_right_side_link"/>
  </joint>
  <link name="head_tilt_right_side_link">
    <inertial>
      <mass value="0.00001"/>
      <origin xyz="0 0 0"/>
      <inertia ixx="1.0" ixy="0.0" ixz="0.0" iyy="1.0" iyz="0.0" izz="1.0"/>
    </inertial>
    <visual>
      <origin rpy="0 0 0" xyz=" 0 0 0 "/>
      <geometry>
        <mesh filename="package://roswell_defs/meshes/F3.stl" scale="0.001 0.001 0.001"/>
      </geometry>
      <material name="Black"/>
    </visual>
    <collision>
      <origin rpy="0 0 0" xyz="0.0 0.0 -0.0045"/>
      <geometry>
        <box size="0.025 0.038 0.009"/>
      </geometry>
    </collision>
  </link>
  <joint name="head_tilt_servo_joint" type="fixed">
    <origin rpy="0 0 0" xyz="0 0 0.0415"/>
    <parent link="head_pan_link"/>
    <child link="head_tilt_servo_link"/>
  </joint>
  <link name="head_tilt_servo_link">
    <inertial>
      <mass value="0.0535"/> <!-- ax-12 -->
      <origin xyz="0 0 0"/>
      <inertia ixx="0.002" ixy="0" ixz="0" iyx="0.002" iyy="0.002" iyz="0" izx="0.002" izy="0" izz="0.002" />
    </inertial>
    <visual>
      <origin rpy="0 0 0" xyz=" 0 0 0 "/>
      <geometry>
        <mesh filename="package://roswell_defs/meshes/ax12.stl" scale="0.001 0.001 0.001"/>
      </geometry>
      <material name="Black"/>
    </visual>
    <collision>
      <origin rpy="0 0 0" xyz="0.0 0.0 -0.01345"/>
      <geometry>
        <box size="0.032 0.040 0.0501"/>
      </geometry>
    </collision>
  </link>
  <joint name="head_tilt_joint" type="revolute">
    <origin rpy="0 0 0" xyz="0 0 0"/>
    <axis xyz="0 1 0"/>
    <limit effort="30" lower="-1.57079632679" upper="1.57079632679" velocity="1.0"/>
    <parent link="head_tilt_servo_link"/>
    <child link="head_tilt_link"/>
  </joint>
  <link name="head_tilt_link">
    <inertial>
      <mass value="0.0535"/> 
      <origin xyz="0 0 0"/>
      <inertia ixx="1.0" ixy="0.0" ixz="0.0" iyy="1.0" iyz="0.0" izz="1.0"/>
-    </inertial>
    <visual>
      <origin rpy="0 0 0" xyz=" 0 0 0 "/>
      <geometry>
        <mesh filename="package://roswell_defs/meshes/F2.stl" scale="0.001 0.001 0.001"/>
      </geometry>
      <material name="Orange"/>
    </visual>
    <collision>
      <origin rpy="0 0 0" xyz="0.0 0.0 0.00775"/>
      <geometry>
        <box size="0.025 0.0485 0.0375"/>
      </geometry>
    </collision>
  </link>
  <link name="head_camera_link" >
    <inertial>
      <!-- asus weight -->
      <mass value="0.226796"/>
      <origin xyz="0 0 0"/>
      <inertia ixx="1.0" ixy="0.0" ixz="0.0" iyy="1.0" iyz="0.0" izz="1.0"/>
    </inertial>

    <visual>
      <origin rpy="0 0 -1.57" xyz="0 0 0"/>
      <geometry>
        <mesh filename="package://roswell_defs/meshes/xtion.stl" scale="0.001 0.001 0.001"/>
      </geometry>
      <material name="Black"/>
    </visual>
    <collision>
<!--
      <origin rpy="0 0 -1.57" xyz="0 0 0"/>
-->
      <origin rpy="0 0 0" xyz="0 0.0 0.02"/>
      <geometry>
        <box size="0.0381 0.1793875 0.0254"/>
      </geometry>
    </collision>
  </link>

<!--
Ran into the following:
http://answers.gazebosim.org/question/4266/gazebo-15-libgazebo_openni_kinectso-pointcloud-data-is-rotated-and-flipped/

The workaround was to use the following head camera urdf from Fetch.
-->

  <joint name="head_camera_joint" type="fixed">
    <origin rpy="0 0 0" xyz="0.0 0.0 0.02" />
    <parent link="head_tilt_link" />
    <child link="head_camera_link" />
  </joint>
  <link name="head_camera_rgb_frame" />
  <joint name="head_camera_rgb_joint" type="fixed">
    <origin rpy="0 0 0" xyz="0 0.02 0" />
    <parent link="head_camera_link" />
    <child link="head_camera_rgb_frame" />
  </joint>
  <link name="head_camera_rgb_optical_frame" />
  <joint name="head_camera_rgb_optical_joint" type="fixed">
    <origin rpy="-1.57079632679 0 -1.57079632679" xyz="0 0 0" />
    <parent link="head_camera_rgb_frame" />
    <child link="head_camera_rgb_optical_frame" />
  </joint>
  <link name="head_camera_depth_frame" />
  <joint name="head_camera_depth_joint" type="fixed">
    <origin rpy="0 0 0" xyz="0 0.045 0" />
    <parent link="head_camera_link" />
    <child link="head_camera_depth_frame" />
  </joint>
  <link name="head_camera_depth_optical_frame" />
  <joint name="head_camera_depth_optical_joint" type="fixed">
    <origin rpy="-1.57079632679 0 -1.57079632679" xyz="0 0 0" />
    <parent link="head_camera_depth_frame" />
    <child link="head_camera_depth_optical_frame" />
  </joint>

<!-- ARD MISSING -->
<transmission type="transmission_interface/SimpleTransmission" name="arm_shoulder_pan_trans">
  <joint name="arm_shoulder_pan_joint">
      <hardwareInterface>PositionJointInterface</hardwareInterface>
  </joint>
  <actuator name="arm_shoulder_pan_motor">
      <hardwareInterface>PositionJointInterface</hardwareInterface>
      <mechanicalReduction>1</mechanicalReduction>
  </actuator>
  <type>transmission_interface/SimpleTransmission</type>
</transmission>
<transmission type="transmission_interface/SimpleTransmission" name="arm_shoulder_lift_trans">
  <joint name="arm_shoulder_lift_joint">
      <hardwareInterface>PositionJointInterface</hardwareInterface>
<!--
      <mass value="2.25" />
      <inertia ixx="0.3354" ixy="0.0" ixz="-0.0162" iyx="0.0" iyy="0.3354" iyz="-0.0006" izx="-0.0162" izy="-0.0006" izz="0.0954" />
-->
  </joint>
  <actuator name="arm_shoulder_lift_motor">
      <hardwareInterface>PositionJointInterface</hardwareInterface>
      <mechanicalReduction>1</mechanicalReduction>
  </actuator>
  <type>transmission_interface/SimpleTransmission</type>
</transmission>
<transmission type="transmission_interface/SimpleTransmission" name="arm_upperarm_roll_trans">
  <joint name="arm_upperarm_roll_joint">
      <hardwareInterface>PositionJointInterface</hardwareInterface>
  </joint>
  <actuator name="arm_upperarm_roll_motor">
      <hardwareInterface>PositionJointInterface</hardwareInterface>
      <mechanicalReduction>1</mechanicalReduction>
  </actuator>
  <type>transmission_interface/SimpleTransmission</type>
</transmission>
<transmission type="transmission_interface/SimpleTransmission" name="arm_elbow_flex_trans">
  <joint name="arm_elbow_flex_joint">
      <hardwareInterface>PositionJointInterface</hardwareInterface>
  </joint>
  <actuator name="arm_upperarm_roll_motor">
      <hardwareInterface>PositionJointInterface</hardwareInterface>
      <mechanicalReduction>1</mechanicalReduction>
  </actuator>
  <type>transmission_interface/SimpleTransmission</type>
</transmission>
<transmission type="transmission_interface/SimpleTransmission" name="arm_wrist_flex_trans">
  <joint name="arm_wrist_flex_joint">
      <hardwareInterface>PositionJointInterface</hardwareInterface>
  </joint>
  <actuator name="arm_wrist_flex_motor">
      <hardwareInterface>PositionJointInterface</hardwareInterface>
      <mechanicalReduction>1</mechanicalReduction>
  </actuator>
  <type>transmission_interface/SimpleTransmission</type>
</transmission>
<transmission type="transmission_interface/SimpleTransmission" name="arm_wrist_roll_trans">
  <joint name="arm_wrist_roll_joint">
      <hardwareInterface>PositionJointInterface</hardwareInterface>
  </joint>
  <actuator name="arm_wrist_roll_motor">
      <hardwareInterface>ace</hardwareInterface>
      <mechanicalReduction>1</mechanicalReduction>
  </actuator>
  <type>transmission_interface/SimpleTransmission</type>
</transmission>
<transmission type="transmission_interface/SimpleTransmission" name="l_gipper_trans">
  <joint name="l_gripper_joint">
      <hardwareInterface>PositionJointInterface</hardwareInterface>
  </joint>
  <actuator name="l_gripper_motor">
      <hardwareInterface>PositionJointInterface</hardwareInterface>
      <mechanicalReduction>1</mechanicalReduction>
  </actuator>
  <type>transmission_interface/SimpleTransmission</type>
</transmission>
<transmission type="transmission_interface/SimpleTransmission" name="r_gipper_trans">
  <joint name="r_gripper_joint">
      <hardwareInterface>PositionJointInterface</hardwareInterface>
  </joint>
  <actuator name="r_gripper_motor">
      <hardwareInterface>PositionJointInterface</hardwareInterface>
      <mechanicalReduction>1</mechanicalReduction>
  </actuator>
  <type>transmission_interface/SimpleTransmission</type>
</transmission>
<transmission type="transmission_interface/SimpleTransmission" name="head_pan_trans">
  <joint name="head_pan_joint">
      <hardwareInterface>PositionJointInterface</hardwareInterface>
  </joint>
  <actuator name="head_pan_motor">
      <hardwareInterface>PositionJointInterface</hardwareInterface>
      <mechanicalReduction>1</mechanicalReduction>
  </actuator>
  <type>transmission_interface/SimpleTransmission</type>
</transmission>
<transmission type="transmission_interface/SimpleTransmission" name="head_tilt_trans">
  <joint name="head_tilt_joint">
      <hardwareInterface>PositionJointInterface</hardwareInterface>
  </joint>
  <actuator name="head_tilt_motor">
      <hardwareInterface>PositionJointInterface</hardwareInterface>
      <mechanicalReduction>1</mechanicalReduction>
  </actuator>
  <type>transmission_interface/SimpleTransmission</type>
</transmission>
<transmission type="transmission_interface/SimpleTransmission" name="arm_lift_trans">
  <joint name="arm_lift_joint">
      <hardwareInterface>PositionJointInterface</hardwareInterface>
  </joint>
  <actuator name="arm_lift_motor">
      <hardwareInterface>PositionJointInterface</hardwareInterface>
      <mechanicalReduction>1</mechanicalReduction>
  </actuator>
  <type>transmission_interface/SimpleTransmission</type>
</transmission>
<!-- no transmission on Turtlebot3 wheels?
<transmission type="transmission_interface/SimpleTransmission" name="base_l_wheel_trans">
  <joint name="base_l_wheel_joint">
<!-
      <hardwareInterface>PositionJointInterface</hardwareInterface>
->
      <hardwareInterface>VelocityJointInterface</hardwareInterface>
      <!-motorTorqueConstant>10</motorTorqueConstant->
  </joint>
  <actuator name="base_l_wheel_motor">
<!-
      <hardwareInterface>PositionJointInterface</hardwareInterface>
->
      <hardwareInterface>VelocityJointInterface</hardwareInterface>
      <mechanicalReduction>1</mechanicalReduction>
  </actuator>
  <type>transmission_interface/SimpleTransmission</type>
</transmission>
<transmission type="transmission_interface/SimpleTransmission" name="base_r_wheel_trans">
  <joint name="base_r_wheel_joint">
<!-
      <hardwareInterface>PositionJointInterface</hardwareInterface>
->
      <hardwareInterface>VelocityJointInterface</hardwareInterface>
  </joint>
  <actuator name="base_r_wheel_motor">
<!-
      <hardwareInterface>PositionJointInterface</hardwareInterface>
->
      <hardwareInterface>VelocityJointInterface</hardwareInterface>
      <mechanicalReduction>1</mechanicalReduction>
  </actuator>
  <type>transmission_interface/SimpleTransmission</type>
</transmission>
-->

<!--
  <transmission name="tran1">
    <type>transmission_interface/SimpleTransmission</type>
    <joint name="joint1"/>
    <actuator name="motor1">
      <hardwareInterface>PositionJointInterface</hardwareInterface>
      <mechanicalReduction>1</mechanicalReduction>
    </actuator>
  </transmission>
-->
</robot>
